**try 语句测试代码块的错误。** 
**catch 语句处理错误。** 
**throw 语句创建自定义错误。** 
**finally 语句在 try 和 catch 语句之后，无论是否有触发异常，该语句都会执行。**

```
 try {
   ...  // 错误的代码块
 } catch(e) {
   ...  // 当 try 代码块发生错误时，所执行的代码块
 } finally {
   ...  // 不论之前的 try 和 catch 中是否产生异常都会执行该代码块
 }

var txt=""; 
function message() {
  try { 
    adddlert("Welcome guest!")
  } catch(err) { 
    txt="本页有一个错误。"
    alert(txt);
  } 
} // 本页有一个错误
```

**throw 语句允许我们创建自定义错误**

```
function myFunction() {
  var message, x;
  message = document.getElementById("p01");
  message.innerHTML = "";
  x = document.getElementById("demo").value;
  try { 
    if(x == "") throw "值是空的";
    if(isNaN(x)) throw "值不是一个数字";
    x = Number(x);
    if(x > 10) throw "太大";
    if(x < 5) throw "太小";
  }
  catch(err) {
    message.innerHTML = "错误: " + err + ".";
  }
  finally {
    document.getElementById("demo").value = "";
  }
}
```


